Workbook
Name Slicer_Country: #N/A
Name Slicer_Region: #N/A
Name Slicer_Sales: #N/A

Sheet Data
A1: Order ID | B1: Order Date | C1: Year | D1: Month | E1: Region | F1: Country | G1: Category | H1: Sub-Category | I1: Customer Segment | J1: Sales | K1: Quantity | L1: Discount | M1: Cost | N1: Profit | O1: Unit Price
A2: ORD2000 | B2: 45467 | C2: 2024 | D2: June | E2: North | F2: UK | G2: Furniture | H2: Storage | I2: Corporate | J2: 20012.71 | K2: 6 | L2: 0.05 | M2: 15106.38 | N2: 4906.33 | O2: =J2/K2 -> 3335.4517
A3: ORD2001 | B3: 45488 | C3: 2024 | D3: July | E3: East | F3: India | G3: Furniture | H3: Storage | I3: Home Office | J3: 32526.73 | K3: 6 | L3: 0.17 | M3: 23572.63 | N3: 8954.1 | O3: =J3/K3 -> 5421.1217
A4: ORD2002 | B4: 45317 | C4: 2024 | D4: January | E4: Central | F4: India | G4: Office Supplies | H4: Tables | I4: Home Office | J4: 4927.51 | K4: 1 | L4: 0.12 | M4: 4078.38 | N4: 849.13 | O4: =J4/K4 -> 4927.51
A5: ORD2003 | B5: 45359 | C5: 2024 | D5: March | E5: North | F5: UK | G5: Furniture | H5: Tables | I5: Corporate | J5: 38088.83 | K5: 2 | L5: 0.23 | M5: 27212.31 | N5: 10876.52 | O5: =J5/K5 -> 19044.415
A6: ORD2004 | B6: 45503 | C6: 2024 | D6: July | E6: North | F6: Germany | G6: Technology | H6: Storage | I6: Home Office | J6: 19018.79 | K6: 2 | L6: 0.22 | M6: 15518.61 | N6: 3500.18 | O6: =J6/K6 -> 9509.395
A7: ORD2005 | B7: 45395 | C7: 2024 | D7: April | E7: Central | F7: Australia | G7: Office Supplies | H7: Chairs | I7: Home Office | J7: 13800.67 | K7: 6 | L7: 0.09 | M7: 9746.46 | N7: 4054.21 | O7: =J7/K7 -> 2300.1117
A8: ORD2006 | B8: 45640 | C8: 2024 | D8: December | E8: South | F8: USA | G8: Furniture | H8: Chairs | I8: Corporate | J8: 31318.96 | K8: 9 | L8: 0.1 | M8: 24472.12 | N8: 6846.84 | O8: =J8/K8 -> 3479.8844
A9: ORD2007 | B9: 45477 | C9: 2024 | D9: July | E9: North | F9: Germany | G9: Technology | H9: Tables | I9: Corporate | J9: 10853.73 | K9: 10 | L9: 0.23 | M9: 8411.58 | N9: 2442.15 | O9: =J9/K9 -> 1085.373
A10: ORD2008 | B10: 45315 | C10: 2024 | D10: January | E10: East | F10: India | G10: Furniture | H10: Tables | I10: Home Office | J10: 6540.32 | K10: 3 | L10: 0.24 | M10: 5549.91 | N10: 990.41 | O10: =J10/K10 -> 2180.1067
A11: ORD2009 | B11: 45364 | C11: 2024 | D11: March | E11: North | F11: Australia | G11: Office Supplies | H11: Binders | I11: Home Office | J11: 10918.37 | K11: 4 | L11: 0.2 | M11: 6613.21 | N11: 4305.16 | O11: =J11/K11 -> 2729.5925
A12: ORD2010 | B12: 45637 | C12: 2024 | D12: December | E12: West | F12: Australia | G12: Technology | H12: Chairs | I12: Home Office | J12: 27163.21 | K12: 10 | L12: 0.02 | M12: 17088.96 | N12: 10074.25 | O12: =J12/K12 -> 2716.321
A13: ORD2011 | B13: 45334 | C13: 2024 | D13: February | E13: North | F13: Germany | G13: Technology | H13: Phones | I13: Home Office | J13: 4746.18 | K13: 11 | L13: 0.01 | M13: 3260.06 | N13: 1486.12 | O13: =J13/K13 -> 431.47091
... A201: ORD2199 | B201: 45533 | C201: 2024 | D201: August | E201: South | F201: Australia | G201: Furniture | H201: Phones | I201: Corporate | J201: 28076.03 | K201: 2 | L201: 0.03 | M201: 16368.5 | N201: 11707.53 | O201: =J201/K201 -> 14038.015

Sheet Index & Match
A2: Applied INDEX and MATCH functions for flexible and accurate data lookup across multiple datasets
A6: Order ID | B6: Sales | C6: Quantity | D6: Profit | E6: Region
A7: ORD2000 | B7: =INDEX(Data!A1:O201,MATCH('Index & Match'!A7,Data!A1:A201,0),10) -> 20012.71 | C7: =INDEX(Data!A1:O201,MATCH('Index & Match'!A7,Data!A1:A201,0),11) -> 6 | D7: =INDEX(Data!A1:O201,MATCH('Index & Match'!A7,Data!A1:A201,0),14) -> 4906.33 | E7: =INDEX(Data!A1:O201,MATCH('Index & Match'!A7,Data!A1:A201,0),5) -> North
A8: ORD2001 | B8: =INDEX(Data!A2:O202,MATCH('Index & Match'!A8,Data!A2:A202,0),10) -> 32526.73 | C8: =INDEX(Data!A2:O202,MATCH('Index & Match'!A8,Data!A2:A202,0),11) -> 6 | D8: =INDEX(Data!A2:O202,MATCH('Index & Match'!A8,Data!A2:A202,0),14) -> 8954.1 | E8: =INDEX(Data!A2:O202,MATCH('Index & Match'!A8,Data!A2:A202,0),5) -> East
A9: ORD2002 | B9: =INDEX(Data!A3:O203,MATCH('Index & Match'!A9,Data!A3:A203,0),10) -> 4927.51 | C9: =INDEX(Data!A3:O203,MATCH('Index & Match'!A9,Data!A3:A203,0),11) -> 1 | D9: =INDEX(Data!A3:O203,MATCH('Index & Match'!A9,Data!A3:A203,0),14) -> 849.13 | E9: =INDEX(Data!A3:O203,MATCH('Index & Match'!A9,Data!A3:A203,0),5) -> Central
A10: ORD2003 | B10: =INDEX(Data!A4:O204,MATCH('Index & Match'!A10,Data!A4:A204,0),10) -> 38088.83 | C10: =INDEX(Data!A4:O204,MATCH('Index & Match'!A10,Data!A4:A204,0),11) -> 2 | D10: =INDEX(Data!A4:O204,MATCH('Index & Match'!A10,Data!A4:A204,0),14) -> 10876.52 | E10: =INDEX(Data!A4:O204,MATCH('Index & Match'!A10,Data!A4:A204,0),5) -> North
A11: ORD2004 | B11: =INDEX(Data!A5:O205,MATCH('Index & Match'!A11,Data!A5:A205,0),10) -> 19018.79 | C11: =INDEX(Data!A5:O205,MATCH('Index & Match'!A11,Data!A5:A205,0),11) -> 2 | D11: =INDEX(Data!A5:O205,MATCH('Index & Match'!A11,Data!A5:A205,0),14) -> 3500.18 | E11: =INDEX(Data!A5:O205,MATCH('Index & Match'!A11,Data!A5:A205,0),5) -> North
A12: ORD2005 | B12: =INDEX(Data!A6:O206,MATCH('Index & Match'!A12,Data!A6:A206,0),10) -> 13800.67 | C12: =INDEX(Data!A6:O206,MATCH('Index & Match'!A12,Data!A6:A206,0),11) -> 6 | D12: =INDEX(Data!A6:O206,MATCH('Index & Match'!A12,Data!A6:A206,0),14) -> 4054.21 | E12: =INDEX(Data!A6:O206,MATCH('Index & Match'!A12,Data!A6:A206,0),5) -> Central
A13: ORD2006 | B13: =INDEX(Data!A7:O207,MATCH('Index & Match'!A13,Data!A7:A207,0),10) -> 31318.96 | C13: =INDEX(Data!A7:O207,MATCH('Index & Match'!A13,Data!A7:A207,0),11) -> 9 | D13: =INDEX(Data!A7:O207,MATCH('Index & Match'!A13,Data!A7:A207,0),14) -> 6846.84 | E13: =INDEX(Data!A7:O207,MATCH('Index & Match'!A13,Data!A7:A207,0),5) -> South
A14: ORD2007 | B14: =INDEX(Data!A8:O208,MATCH('Index & Match'!A14,Data!A8:A208,0),10) -> 10853.73 | C14: =INDEX(Data!A8:O208,MATCH('Index & Match'!A14,Data!A8:A208,0),11) -> 10 | D14: =INDEX(Data!A8:O208,MATCH('Index & Match'!A14,Data!A8:A208,0),14) -> 2442.15 | E14: =INDEX(Data!A8:O208,MATCH('Index & Match'!A14,Data!A8:A208,0),5) -> North
A15: ORD2008 | B15: =INDEX(Data!A9:O209,MATCH('Index & Match'!A15,Data!A9:A209,0),10) -> 6540.32 | C15: =INDEX(Data!A9:O209,MATCH('Index & Match'!A15,Data!A9:A209,0),11) -> 3 | D15: =INDEX(Data!A9:O209,MATCH('Index & Match'!A15,Data!A9:A209,0),14) -> 990.41 | E15: =INDEX(Data!A9:O209,MATCH('Index & Match'!A15,Data!A9:A209,0),5) -> East
A16: ORD2009 | B16: =INDEX(Data!A10:O210,MATCH('Index & Match'!A16,Data!A10:A210,0),10) -> 10918.37 | C16: =INDEX(Data!A10:O210,MATCH('Index & Match'!A16,Data!A10:A210,0),11) -> 4 | D16: =INDEX(Data!A10:O210,MATCH('Index & Match'!A16,Data!A10:A210,0),14) -> 4305.16 | E16: =INDEX(Data!A10:O210,MATCH('Index & Match'!A16,Data!A10:A210,0),5) -> North
A17: ORD2010 | B17: =INDEX(Data!A11:O211,MATCH('Index & Match'!A17,Data!A11:A211,0),10) -> 27163.21 | C17: =INDEX(Data!A11:O211,MATCH('Index & Match'!A17,Data!A11:A211,0),11) -> 10 | D17: =INDEX(Data!A11:O211,MATCH('Index & Match'!A17,Data!A11:A211,0),14) -> 10074.25 | E17: =INDEX(Data!A11:O211,MATCH('Index & Match'!A17,Data!A11:A211,0),5) -> West
A18: ORD2011 | B18: =INDEX(Data!A12:O212,MATCH('Index & Match'!A18,Data!A12:A212,0),10) -> 4746.18 | C18: =INDEX(Data!A12:O212,MATCH('Index & Match'!A18,Data!A12:A212,0),11) -> 11 | D18: =INDEX(Data!A12:O212,MATCH('Index & Match'!A18,Data!A12:A212,0),14) -> 1486.12 | E18: =INDEX(Data!A12:O212,MATCH('Index & Match'!A18,Data!A12:A212,0),5) -> North
... A206: ORD2199 | B206: =INDEX(Data!A200:O400,MATCH('Index & Match'!A206,Data!A200:A400,0),10) -> 28076.03 | C206: =INDEX(Data!A200:O400,MATCH('Index & Match'!A206,Data!A200:A400,0),11) -> 2 | D206: =INDEX(Data!A200:O400,MATCH('Index & Match'!A206,Data!A200:A400,0),14) -> 11707.53 | E206: =INDEX(Data!A200:O400,MATCH('Index & Match'!A206,Data!A200:A400,0),5) -> South

Sheet VLookUp
A3: I used VLOOKUP to retrieve sales, region, country, quantity, profit, and unit price details for different Order IDs.
A6: Order ID | B6: Sales | C6: Region | D6: Country | E6: Quantity | F6: Profit | G6: Unit Price
A7: ORD2000 | B7: =VLOOKUP(A7,Data!$A$1:$N$201,10,0) -> 20012.71 | C7: =VLOOKUP(A7,Data!$A$1:$N$201,5,0) -> North | D7: =VLOOKUP(A7,Data!$A$1:$N$201,6,0) -> UK | E7: =VLOOKUP(A7,Data!$A$1:$N$201,11,0) -> 6 | F7: =VLOOKUP(A7,Data!A1:N201,14,0) -> 4906.33 | G7: =VLOOKUP(A7,Data!$A$1:$O$201,15,0) -> 3335.4517
A8: ORD2001 | B8: =VLOOKUP(A8,Data!$A$1:$N$201,10,0) -> 32526.73 | C8: =VLOOKUP(A8,Data!$A$1:$N$201,5,0) -> East | D8: =VLOOKUP(A8,Data!$A$1:$N$201,6,0) -> India | E8: =VLOOKUP(A8,Data!$A$1:$N$201,11,0) -> 6 | F8: =VLOOKUP(A8,Data!A2:N202,14,0) -> 8954.1 | G8: =VLOOKUP(A8,Data!$A$1:$O$201,15,0) -> 5421.1217
A9: ORD2002 | B9: =VLOOKUP(A9,Data!$A$1:$N$201,10,0) -> 4927.51 | C9: =VLOOKUP(A9,Data!$A$1:$N$201,5,0) -> Central | D9: =VLOOKUP(A9,Data!$A$1:$N$201,6,0) -> India | E9: =VLOOKUP(A9,Data!$A$1:$N$201,11,0) -> 1 | F9: =VLOOKUP(A9,Data!A3:N203,14,0) -> 849.13 | G9: =VLOOKUP(A9,Data!$A$1:$O$201,15,0) -> 4927.51
A10: ORD2003 | B10: =VLOOKUP(A10,Data!$A$1:$N$201,10,0) -> 38088.83 | C10: =VLOOKUP(A10,Data!$A$1:$N$201,5,0) -> North | D10: =VLOOKUP(A10,Data!$A$1:$N$201,6,0) -> UK | E10: =VLOOKUP(A10,Data!$A$1:$N$201,11,0) -> 2 | F10: =VLOOKUP(A10,Data!A4:N204,14,0) -> 10876.52 | G10: =VLOOKUP(A10,Data!$A$1:$O$201,15,0) -> 19044.415
A11: ORD2004 | B11: =VLOOKUP(A11,Data!$A$1:$N$201,10,0) -> 19018.79 | C11: =VLOOKUP(A11,Data!$A$1:$N$201,5,0) -> North | D11: =VLOOKUP(A11,Data!$A$1:$N$201,6,0) -> Germany | E11: =VLOOKUP(A11,Data!$A$1:$N$201,11,0) -> 2 | F11: =VLOOKUP(A11,Data!A5:N205,14,0) -> 3500.18 | G11: =VLOOKUP(A11,Data!$A$1:$O$201,15,0) -> 9509.395
A12: ORD2005 | B12: =VLOOKUP(A12,Data!$A$1:$N$201,10,0) -> 13800.67 | C12: =VLOOKUP(A12,Data!$A$1:$N$201,5,0) -> Central | D12: =VLOOKUP(A12,Data!$A$1:$N$201,6,0) -> Australia | E12: =VLOOKUP(A12,Data!$A$1:$N$201,11,0) -> 6 | F12: =VLOOKUP(A12,Data!A6:N206,14,0) -> 4054.21 | G12: =VLOOKUP(A12,Data!$A$1:$O$201,15,0) -> 2300.1117
A13: ORD2006 | B13: =VLOOKUP(A13,Data!$A$1:$N$201,10,0) -> 31318.96 | C13: =VLOOKUP(A13,Data!$A$1:$N$201,5,0) -> South | D13: =VLOOKUP(A13,Data!$A$1:$N$201,6,0) -> USA | E13: =VLOOKUP(A13,Data!$A$1:$N$201,11,0) -> 9 | F13: =VLOOKUP(A13,Data!A7:N207,14,0) -> 6846.84 | G13: =VLOOKUP(A13,Data!$A$1:$O$201,15,0) -> 3479.8844
A14: ORD2007 | B14: =VLOOKUP(A14,Data!$A$1:$N$201,10,0) -> 10853.73 | C14: =VLOOKUP(A14,Data!$A$1:$N$201,5,0) -> North | D14: =VLOOKUP(A14,Data!$A$1:$N$201,6,0) -> Germany | E14: =VLOOKUP(A14,Data!$A$1:$N$201,11,0) -> 10 | F14: =VLOOKUP(A14,Data!A8:N208,14,0) -> 2442.15 | G14: =VLOOKUP(A14,Data!$A$1:$O$201,15,0) -> 1085.373
A15: ORD2008 | B15: =VLOOKUP(A15,Data!$A$1:$N$201,10,0) -> 6540.32 | C15: =VLOOKUP(A15,Data!$A$1:$N$201,5,0) -> East | D15: =VLOOKUP(A15,Data!$A$1:$N$201,6,0) -> India | E15: =VLOOKUP(A15,Data!$A$1:$N$201,11,0) -> 3 | F15: =VLOOKUP(A15,Data!A9:N209,14,0) -> 990.41 | G15: =VLOOKUP(A15,Data!$A$1:$O$201,15,0) -> 2180.1067
A16: ORD2009 | B16: =VLOOKUP(A16,Data!$A$1:$N$201,10,0) -> 10918.37 | C16: =VLOOKUP(A16,Data!$A$1:$N$201,5,0) -> North | D16: =VLOOKUP(A16,Data!$A$1:$N$201,6,0) -> Australia | E16: =VLOOKUP(A16,Data!$A$1:$N$201,11,0) -> 4 | F16: =VLOOKUP(A16,Data!A10:N210,14,0) -> 4305.16 | G16: =VLOOKUP(A16,Data!$A$1:$O$201,15,0) -> 2729.5925
A17: ORD2010 | B17: =VLOOKUP(A17,Data!$A$1:$N$201,10,0) -> 27163.21 | C17: =VLOOKUP(A17,Data!$A$1:$N$201,5,0) -> West | D17: =VLOOKUP(A17,Data!$A$1:$N$201,6,0) -> Australia | E17: =VLOOKUP(A17,Data!$A$1:$N$201,11,0) -> 10 | F17: =VLOOKUP(A17,Data!A11:N211,14,0) -> 10074.25 | G17: =VLOOKUP(A17,Data!$A$1:$O$201,15,0) -> 2716.321
A18: ORD2011 | B18: =VLOOKUP(A18,Data!$A$1:$N$201,10,0) -> 4746.18 | C18: =VLOOKUP(A18,Data!$A$1:$N$201,5,0) -> North | D18: =VLOOKUP(A18,Data!$A$1:$N$201,6,0) -> Germany | E18: =VLOOKUP(A18,Data!$A$1:$N$201,11,0) -> 11 | F18: =VLOOKUP(A18,Data!A12:N212,14,0) -> 1486.12 | G18: =VLOOKUP(A18,Data!$A$1:$O$201,15,0) -> 431.47091
... A206: ORD2199 | B206: =VLOOKUP(A206,Data!$A$1:$N$201,10,0) -> 28076.03 | C206: =VLOOKUP(A206,Data!$A$1:$N$201,5,0) -> South | D206: =VLOOKUP(A206,Data!$A$1:$N$201,6,0) -> Australia | E206: =VLOOKUP(A206,Data!$A$1:$N$201,11,0) -> 2 | F206: =VLOOKUP(A206,Data!A200:N400,14,0) -> 11707.53 | G206: =VLOOKUP(A206,Data!$A$1:$O$201,15,0) -> 14038.015

Sheet HLookUp
A3: I used HLOOKUP to retrieve sales, quantity, and profit for different Order IDs.
A5: Order ID | B5: ORD2000 | C5: ORD2001 | D5: ORD2002 | E5: ORD2003 | F5: ORD2004 | G5: ORD2005 | H5: ORD2006 | I5: ORD2007 | J5: ORD2008 | K5: ORD2009 | L5: ORD2010 | M5: ORD2011 | N5: ORD2012 | O5: ORD2013 | P5: ORD2014 | Q5: ORD2015 | R5: ORD2016 | S5: ORD2017 | T5: ORD2018 | U5: ORD2019 | V5: ORD2020 | W5: ORD2021 | X5: ORD2022 | Y5: ORD2023 | Z5: ORD2024 | AA5: ORD2025 | AB5: ORD2026 | AC5: ORD2027 | AD5: ORD2028 | AE5: ORD2029 | AF5: ORD2030 | AG5: ORD2031 | AH5: ORD2032 | AI5: ORD2033 | AJ5: ORD2034 | AK5: ORD2035 | AL5: ORD2036 | AM5: ORD2037 | AN5: ORD2038 | AO5: ORD2039 | AP5: ORD2040 | AQ5: ORD2041 | AR5: ORD2042 | AS5: ORD2043 | AT5: ORD2044 | AU5: ORD2045 | AV5: ORD2046 | AW5: ORD2047 | AX5: ORD2048 | AY5: ORD2049 | AZ5: ORD2050 | BA5: ORD2051 | BB5: ORD2052 | BC5: ORD2053 | BD5: ORD2054 | BE5: ORD2055 | BF5: ORD2056 | BG5: ORD2057 | BH5: ORD2058 | BI5: ORD2059 | BJ5: ORD2060 | BK5: ORD2061 | BL5: ORD2062 | BM5: ORD2063 | BN5: ORD2064 | BO5: ORD2065 | BP5: ORD2066 | BQ5: ORD2067 | BR5: ORD2068 | BS5: ORD2069 | BT5: ORD2070 | BU5: ORD2071 | BV5: ORD2072 | BW5: ORD2073 | BX5: ORD2074 | BY5: ORD2075 | BZ5: ORD2076 | CA5: ORD2077 | CB5: ORD2078 | CC5: ORD2079 | CD5: ORD2080 | CE5: ORD2081 | CF5: ORD2082 | CG5: ORD2083 | CH5: ORD2084 | CI5: ORD2085 | CJ5: ORD2086 | CK5: ORD2087 | CL5: ORD2088 | CM5: ORD2089 | CN5: ORD2090 | CO5: ORD2091 | CP5: ORD2092 | CQ5: ORD2093 | CR5: ORD2094 | CS5: ORD2095 | CT5: ORD2096 | CU5: ORD2097 | CV5: ORD2098 | CW5: ORD2099 | CX5: ORD2100 | CY5: ORD2101 | CZ5: ORD2102 | DA5: ORD2103 | DB5: ORD2104 | DC5: ORD2105 | DD5: ORD2106 | DE5: ORD2107 | DF5: ORD2108 | DG5: ORD2109 | DH5: ORD2110 | DI5: ORD2111 | DJ5: ORD2112 | DK5: ORD2113 | DL5: ORD2114 | DM5: ORD2115 | DN5: ORD2116 | DO5: ORD2117 | DP5: ORD2118 | DQ5: ORD2119 | DR5: ORD2120 | DS5: ORD2121 | DT5: ORD2122 | DU5: ORD2123 | DV5: ORD2124 | DW5: ORD2125 | DX5: ORD2126 | DY5: ORD2127 | DZ5: ORD2128 | EA5: ORD2129 | EB5: ORD2130 | EC5: ORD2131 | ED5: ORD2132 | EE5: ORD2133 | EF5: ORD2134 | EG5: ORD2135 | EH5: ORD2136 | EI5: ORD2137 | EJ5: ORD2138 | EK5: ORD2139 | EL5: ORD2140 | EM5: ORD2141 | EN5: ORD2142 | EO5: ORD2143 | EP5: ORD2144 | EQ5: ORD2145 | ER5: ORD2146 | ES5: ORD2147 | ET5: ORD2148 | EU5: ORD2149 | EV5: ORD2150 | EW5: ORD2151 | EX5: ORD2152 | EY5: ORD2153 | EZ5: ORD2154 | FA5: ORD2155 | FB5: ORD2156 | FC5: ORD2157 | FD5: ORD2158 | FE5: ORD2159 | FF5: ORD2160 | FG5: ORD2161 | FH5: ORD2162 | FI5: ORD2163 | FJ5: ORD2164 | FK5: ORD2165 | FL5: ORD2166 | FM5: ORD2167 | FN5: ORD2168 | FO5: ORD2169 | FP5: ORD2170 | FQ5: ORD2171 | FR5: ORD2172 | FS5: ORD2173 | FT5: ORD2174 | FU5: ORD2175 | FV5: ORD2176 | FW5: ORD2177 | FX5: ORD2178 | FY5: ORD2179 | FZ5: ORD2180 | GA5: ORD2181 | GB5: ORD2182 | GC5: ORD2183 | GD5: ORD2184 | GE5: ORD2185 | GF5: ORD2186 | GG5: ORD2187 | GH5: ORD2188 | GI5: ORD2189 | GJ5: ORD2190 | GK5: ORD2191 | GL5: ORD2192 | GM5: ORD2193 | GN5: ORD2194 | GO5: ORD2195 | GP5: ORD2196 | GQ5: ORD2197 | GR5: ORD2198 | GS5: ORD2199
A6: Order Date | B6: 45467 | C6: 45488 | D6: 45317 | E6: 45359 | F6: 45503 | G6: 45395 | H6: 45640 | I6: 45477 | J6: 45315 | K6: 45364 | L6: 45637 | M6: 45334 | N6: 45510 | O6: 45459 | P6: 45360 | Q6: 45292 | R6: 45367 | S6: 45603 | T6: 45542 | U6: 45298 | V6: 45567 | W6: 45336 | X6: 45483 | Y6: 45617 | Z6: 45604 | AA6: 45444 | AB6: 45475 | AC6: 45404 | AD6: 45543 | AE6: 45481 | AF6: 45582 | AG6: 45604 | AH6: 45493 | AI6: 45330 | AJ6: 45552 | AK6: 45429 | AL6: 45635 | AM6: 45487 | AN6: 45364 | AO6: 45631 | AP6: 45549 | AQ6: 45484 | AR6: 45641 | AS6: 45384 | AT6: 45544 | AU6: 45363 | AV6: 45571 | AW6: 45302 | AX6: 45525 | AY6: 45583 | AZ6: 45609 | BA6: 45443 | BB6: 45384 | BC6: 45539 | BD6: 45516 | BE6: 45441 | BF6: 45648 | BG6: 45359 | BH6: 45511 | BI6: 45311 | BJ6: 45296 | BK6: 45567 | BL6: 45325 | BM6: 45415 | BN6: 45578 | BO6: 45477 | BP6: 45521 | BQ6: 45621 | BR6: 45422 | BS6: 45375 | BT6: 45313 | BU6: 45411 | BV6: 45359 | BW6: 45495 | BX6: 45339 | BY6: 45564 | BZ6: 45304 | CA6: 45641 | CB6: 45399 | CC6: 45525 | CD6: 45624 | CE6: 45615 | CF6: 45402 | CG6: 45434 | CH6: 45416 | CI6: 45568 | CJ6: 45601 | CK6: 45607 | CL6: 45327 | CM6: 45596 | CN6: 45552 | CO6: 45591 | CP6: 45542 | CQ6: 45346 | CR6: 45335 | CS6: 45507 | CT6: 45331 | CU6: 45423 | CV6: 45627 | CW6: 45577 | CX6: 45428 | CY6: 45346 | CZ6: 45458 | DA6: 45490 | DB6: 45441 | DC6: 45336 | DD6: 45427 | DE6: 45501 | DF6: 45489 | DG6: 45392 | DH6: 45472 | DI6: 45461 | DJ6: 45321 | DK6: 45574 | DL6: 45612 | DM6: 45544 | DN6: 45482 | DO6: 45506 | DP6: 45518 | DQ6: 45304 | DR6: 45426 | DS6: 45398 | DT6: 45402 | DU6: 45641 | DV6: 45526 | DW6: 45309 | DX6: 45297 | DY6: 45627 | DZ6: 45341 | EA6: 45624 | EB6: 45397 | EC6: 45474 | ED6: 45467 | EE6: 45379 | EF6: 45441 | EG6: 45552 | EH6: 45368 | EI6: 45525 | EJ6: 45623 | EK6: 45554 | EL6: 45517 | EM6: 45377 | EN6: 45450 | EO6: 45655 | EP6: 45604 | EQ6: 45599 | ER6: 45539 | ES6: 45475 | ET6: 45413 | EU6: 45368 | EV6: 45491 | EW6: 45377 | EX6: 45478 | EY6: 45589 | EZ6: 45522 | FA6: 45591 | FB6: 45607 | FC6: 45630 | FD6: 45355 | FE6: 45327 | FF6: 45369 | FG6: 45580 | FH6: 45409 | FI6: 45507 | FJ6: 45453 | FK6: 45337 | FL6: 45408 | FM6: 45337 | FN6: 45653 | FO6: 45334 | FP6: 45644 | FQ6: 45582 | FR6: 45387 | FS6: 45475 | FT6: 45522 | FU6: 45557 | FV6: 45561 | FW6: 45633 | FX6: 45293 | FY6: 45579 | FZ6: 45500 | GA6: 45340 | GB6: 45445 | GC6: 45453 | GD6: 45547 | GE6: 45630 | GF6: 45356 | GG6: 45606 | GH6: 45558 | GI6: 45319 | GJ6: 45448 | GK6: 45300 | GL6: 45539 | GM6: 45392 | GN6: 45546 | GO6: 45602 | GP6: 45590 | GQ6: 45640 | GR6: 45299 | GS6: 45533
A7: Year | B7: 2024 | C7: 2024 | D7: 2024 | E7: 2024 | F7: 2024 | G7: 2024 | H7: 2024 | I7: 2024 | J7: 2024 | K7: 2024 | L7: 2024 | M7: 2024 | N7: 2024 | O7: 2024 | P7: 2024 | Q7: 2024 | R7: 2024 | S7: 2024 | T7: 2024 | U7: 2024 | V7: 2024 | W7: 2024 | X7: 2024 | Y7: 2024 | Z7: 2024 | AA7: 2024 | AB7: 2024 | AC7: 2024 | AD7: 2024 | AE7: 2024 | AF7: 2024 | AG7: 2024 | AH7: 2024 | AI7: 2024 | AJ7: 2024 | AK7: 2024 | AL7: 2024 | AM7: 2024 | AN7: 2024 | AO7: 2024 | AP7: 2024 | AQ7: 2024 | AR7: 2024 | AS7: 2024 | AT7: 2024 | AU7: 2024 | AV7: 2024 | AW7: 2024 | AX7: 2024 | AY7: 2024 | AZ7: 2024 | BA7: 2024 | BB7: 2024 | BC7: 2024 | BD7: 2024 | BE7: 2024 | BF7: 2024 | BG7: 2024 | BH7: 2024 | BI7: 2024 | BJ7: 2024 | BK7: 2024 | BL7: 2024 | BM7: 2024 | BN7: 2024 | BO7: 2024 | BP7: 2024 | BQ7: 2024 | BR7: 2024 | BS7: 2024 | BT7: 2024 | BU7: 2024 | BV7: 2024 | BW7: 2024 | BX7: 2024 | BY7: 2024 | BZ7: 2024 | CA7: 2024 | CB7: 2024 | CC7: 2024 | CD7: 2024 | CE7: 2024 | CF7: 2024 | CG7: 2024 | CH7: 2024 | CI7: 2024 | CJ7: 2024 | CK7: 2024 | CL7: 2024 | CM7: 2024 | CN7: 2024 | CO7: 2024 | CP7: 2024 | CQ7: 2024 | CR7: 2024 | CS7: 2024 | CT7: 2024 | CU7: 2024 | CV7: 2024 | CW7: 2024 | CX7: 2024 | CY7: 2024 | CZ7: 2024 | DA7: 2024 | DB7: 2024 | DC7: 2024 | DD7: 2024 | DE7: 2024 | DF7: 2024 | DG7: 2024 | DH7: 2024 | DI7: 2024 | DJ7: 2024 | DK7: 2024 | DL7: 2024 | DM7: 2024 | DN7: 2024 | DO7: 2024 | DP7: 2024 | DQ7: 2024 | DR7: 2024 | DS7: 2024 | DT7: 2024 | DU7: 2024 | DV7: 2024 | DW7: 2024 | DX7: 2024 | DY7: 2024 | DZ7: 2024 | EA7: 2024 | EB7: 2024 | EC7: 2024 | ED7: 2024 | EE7: 2024 | EF7: 2024 | EG7: 2024 | EH7: 2024 | EI7: 2024 | EJ7: 2024 | EK7: 2024 | EL7: 2024 | EM7: 2024 | EN7: 2024 | EO7: 2024 | EP7: 2024 | EQ7: 2024 | ER7: 2024 | ES7: 2024 | ET7: 2024 | EU7: 2024 | EV7: 2024 | EW7: 2024 | EX7: 2024 | EY7: 2024 | EZ7: 2024 | FA7: 2024 | FB7: 2024 | FC7: 2024 | FD7: 2024 | FE7: 2024 | FF7: 2024 | FG7: 2024 | FH7: 2024 | FI7: 2024 | FJ7: 2024 | FK7: 2024 | FL7: 2024 | FM7: 2024 | FN7: 2024 | FO7: 2024 | FP7: 2024 | FQ7: 2024 | FR7: 2024 | FS7: 2024 | FT7: 2024 | FU7: 2024 | FV7: 2024 | FW7: 2024 | FX7: 2024 | FY7: 2024 | FZ7: 2024 | GA7: 2024 | GB7: 2024 | GC7: 2024 | GD7: 2024 | GE7: 2024 | GF7: 2024 | GG7: 2024 | GH7: 2024 | GI7: 2024 | GJ7: 2024 | GK7: 2024 | GL7: 2024 | GM7: 2024 | GN7: 2024 | GO7: 2024 | GP7: 2024 | GQ7: 2024 | GR7: 2024 | GS7: 2024
A8: Month | B8: June | C8: July | D8: January | E8: March | F8: July | G8: April | H8: December | I8: July | J8: January | K8: March | L8: December | M8: February | N8: August | O8: June | P8: March | Q8: January | R8: March | S8: November | T8: September | U8: January | V8: October | W8: February | X8: July | Y8: November | Z8: November | AA8: June | AB8: July | AC8: April | AD8: September | AE8: July | AF8: October | AG8: November | AH8: July | AI8: February | AJ8: September | AK8: May | AL8: December | AM8: July | AN8: March | AO8: December | AP8: September | AQ8: July | AR8: December | AS8: April | AT8: September | AU8: March | AV8: October | AW8: January | AX8: August | AY8: October | AZ8: November | BA8: May | BB8: April | BC8: September | BD8: August | BE8: May | BF8: December | BG8: March | BH8: August | BI8: January | BJ8: January | BK8: October | BL8: February | BM8: May | BN8: October | BO8: July | BP8: August | BQ8: November | BR8: May | BS8: March | BT8: January | BU8: April | BV8: March | BW8: July | BX8: February | BY8: September | BZ8: January | CA8: December | CB8: April | CC8: August | CD8: November | CE8: November | CF8: April | CG8: May | CH8: May | CI8: October | CJ8: November | CK8: November | CL8: February | CM8: October | CN8: September | CO8: October | CP8: September | CQ8: February | CR8: February | CS8: August | CT8: February | CU8: May | CV8: December | CW8: October | CX8: May | CY8: February | CZ8: June | DA8: July | DB8: May | DC8: February | DD8: May | DE8: July | DF8: July | DG8: April | DH8: June | DI8: June | DJ8: January | DK8: October | DL8: November | DM8: September | DN8: July | DO8: August | DP8: August | DQ8: January | DR8: May | DS8: April | DT8: April | DU8: December | DV8: August | DW8: January | DX8: January | DY8: December | DZ8: February | EA8: November | EB8: April | EC8: July | ED8: June | EE8: March | EF8: May | EG8: September | EH8: March | EI8: August | EJ8: November | EK8: September | EL8: August | EM8: March | EN8: June | EO8: December | EP8: November | EQ8: November | ER8: September | ES8: July | ET8: May | EU8: March | EV8: July | EW8: March | EX8: July | EY8: October | EZ8: August | FA8: October | FB8: November | FC8: December | FD8: March | FE8: February | FF8: March | FG8: October | FH8: April | FI8: August | FJ8: June | FK8: February | FL8: April | FM8: February | FN8: December | FO8: February | FP8: December | FQ8: October | FR8: April | FS8: July | FT8: August | FU8: September | FV8: September | FW8: December | FX8: January | FY8: October | FZ8: July | GA8: February | GB8: June | GC8: June | GD8: September | GE8: December | GF8: March | GG8: November | GH8: September | GI8: January | GJ8: June | GK8: January | GL8: September | GM8: April | GN8: September | GO8: November | GP8: October | GQ8: December | GR8: January | GS8: August
A9: Region | B9: North | C9: East | D9: Central | E9: North | F9: North | G9: Central | H9: South | I9: North | J9: East | K9: North | L9: West | M9: North | N9: South | O9: West | P9: East | Q9: North | R9: North | S9: Central | T9: Central | U9: West | V9: South | W9: East | X9: Central | Y9: North | Z9: Central | AA9: East | AB9: East | AC9: North | AD9: West | AE9: South | AF9: North | AG9: West | AH9: South | AI9: East | AJ9: North | AK9: South | AL9: West | AM9: West | AN9: Central | AO9: West | AP9: South | AQ9: Central | AR9: West | AS9: Central | AT9: North | AU9: South | AV9: East | AW9: East | AX9: North | AY9: Central | AZ9: West | BA9: South | BB9: North | BC9: Central | BD9: South | BE9: North | BF9: East | BG9: Central | BH9: Central | BI9: Central | BJ9: Central | BK9: West | BL9: South | BM9: East | BN9: North | BO9: East | BP9: South | BQ9: East | BR9: North | BS9: East | BT9: Central | BU9: East | BV9: Central | BW9: North | BX9: West | BY9: West | BZ9: North | CA9: Central | CB9: North | CC9: South | CD9: Central | CE9: East | CF9: South | CG9: South | CH9: West | CI9: Central | CJ9: North | CK9: West | CL9: Central | CM9: North | CN9: Central | CO9: South | CP9: East | CQ9: West | CR9: West | CS9: Central | CT9: North | CU9: West | CV9: West | CW9: East | CX9: West | CY9: South | CZ9: South | DA9: North | DB9: Central | DC9: East | DD9: East | DE9: West | DF9: West | DG9: South | DH9: East | DI9: North | DJ9: North | DK9: North | DL9: Central | DM9: South | DN9: East | DO9: West | DP9: Central | DQ9: North | DR9: East | DS9: South | DT9: West | DU9: South | DV9: North | DW9: South | DX9: West | DY9: West | DZ9: West | EA9: East | EB9: Central | EC9: East | ED9: North | EE9: East | EF9: Central | EG9: South | EH9: North | EI9: East | EJ9: North | EK9: East | EL9: East | EM9: Central | EN9: West | EO9: South | EP9: Central | EQ9: Central | ER9: South | ES9: South | ET9: South | EU9: Central | EV9: North | EW9: Central | EX9: East | EY9: Central | EZ9: West | FA9: West | FB9: East | FC9: Central | FD9: West | FE9: East | FF9: Central | FG9: South | FH9: North | FI9: West | FJ9: East | FK9: East | FL9: North | FM9: South | FN9: West | FO9: East | FP9: East | FQ9: East | FR9: Central | FS9: West | FT9: Central | FU9: North | FV9: East | FW9: East | FX9: North | FY9: East | FZ9: North | GA9: East | GB9: North | GC9: Central | GD9: North | GE9: Central | GF9: South | GG9: Central | GH9: Central | GI9: South | GJ9: North | GK9: South | GL9: North | GM9: East | GN9: East | GO9: North | GP9: East | GQ9: Central | GR9: Central | GS9: South
A10: Country | B10: UK | C10: India | D10: India | E10: UK | F10: Germany | G10: Australia | H10: USA | I10: Germany | J10: India | K10: Australia | L10: Australia | M10: Germany | N10: Germany | O10: India | P10: Germany | Q10: Australia | R10: Australia | S10: UK | T10: USA | U10: UK | V10: UK | W10: India | X10: UK | Y10: USA | Z10: India | AA10: India | AB10: Australia | AC10: Germany | AD10: India | AE10: Australia | AF10: Australia | AG10: Australia | AH10: India | AI10: India | AJ10: UK | AK10: Germany | AL10: India | AM10: Australia | AN10: Germany | AO10: UK | AP10: Australia | AQ10: USA | AR10: USA | AS10: Australia | AT10: USA | AU10: USA | AV10: UK | AW10: Germany | AX10: India | AY10: USA | AZ10: Australia | BA10: India | BB10: UK | BC10: UK | BD10: Germany | BE10: USA | BF10: India | BG10: India | BH10: Australia | BI10: India | BJ10: UK | BK10: USA | BL10: USA | BM10: UK | BN10: UK | BO10: India | BP10: Australia | BQ10: USA | BR10: UK | BS10: UK | BT10: Australia | BU10: Australia | BV10: Australia | BW10: Germany | BX10: USA | BY10: USA | BZ10: India | CA10: USA | CB10: India | CC10: UK | CD10: Australia | CE10: UK | CF10: Germany | CG10: USA | CH10: Australia | CI10: India | CJ10: Germany | CK10: Germany | CL10: Germany | CM10: Australia | CN10: USA | CO10: USA | CP10: UK | CQ10: Australia | CR10: USA | CS10: USA | CT10: India | CU10: Germany | CV10: India | CW10: Germany | CX10: UK | CY10: UK | CZ10: UK | DA10: Germany | DB10: USA | DC10: Australia | DD10: USA | DE10: Australia | DF10: USA | DG10: Germany | DH10: UK | DI10: Germany | DJ10: India | DK10: India | DL10: UK | DM10: Australia | DN10: India | DO10: Australia | DP10: Australia | DQ10: Australia | DR10: India | DS10: Australia | DT10: UK | DU10: India | DV10: Germany | DW10: Germany | DX10: USA | DY10: India | DZ10: India | EA10: Germany | EB10: Australia | EC10: Germany | ED10: India | EE10: UK | EF10: USA | EG10: Germany | EH10: UK | EI10: Germany | EJ10: USA | EK10: UK | EL10: Australia | EM10: Australia | EN10: UK | EO10: USA | EP10: USA | EQ10: Australia | ER10: USA | ES10: UK | ET10: USA | EU10: USA | EV10: UK | EW10: India | EX10: India | EY10: Germany | EZ10: UK | FA10: USA | FB10: India | FC10: Australia | FD10: Germany | FE10: Australia | FF10: Australia | FG10: Australia | FH10: India | FI10: UK | FJ10: USA | FK10: Germany | FL10: Australia | FM10: UK | FN10: India | FO10: Germany | FP10: India | FQ10: Germany | FR10: Germany | FS10: India | FT10: India | FU10: India | FV10: Australia | FW10: UK | FX10: Australia | FY10: UK | FZ10: India | GA10: India | GB10: Germany | GC10: Germany | GD10: UK | GE10: Australia | GF10: Germany | GG10: Australia | GH10: India | GI10: UK | GJ10: Germany | GK10: India | GL10: USA | GM10: Germany | GN10: India | GO10: USA | GP10: UK | GQ10: UK | GR10: Germany | GS10: Australia
A11: Category | B11: Furniture | C11: Furniture | D11: Office Supplies | E11: Furniture | F11: Technology | G11: Office Supplies | H11: Furniture | I11: Technology | J11: Furniture | K11: Office Supplies | L11: Technology | M11: Technology | N11: Furniture | O11: Office Supplies | P11: Technology | Q11: Office Supplies | R11: Furniture | S11: Furniture | T11: Furniture | U11: Furniture | V11: Technology | W11: Furniture | X11: Office Supplies | Y11: Office Supplies | Z11: Technology | AA11: Furniture | AB11: Technology | AC11: Furniture | AD11: Office Supplies | AE11: Technology | AF11: Furniture | AG11: Technology | AH11: Technology | AI11: Furniture | AJ11: Technology | AK11: Technology | AL11: Technology | AM11: Office Supplies | AN11: Office Supplies | AO11: Technology | AP11: Office Supplies | AQ11: Technology | AR11: Technology | AS11: Technology | AT11: Office Supplies | AU11: Technology | AV11: Technology | AW11: Office Supplies | AX11: Office Supplies | AY11: Office Supplies | AZ11: Office Supplies | BA11: Furniture | BB11: Technology | BC11: Office Supplies | BD11: Furniture | BE11: Furniture | BF11: Technology | BG11: Technology | BH11: Furniture | BI11: Furniture | BJ11: Furniture | BK11: Office Supplies | BL11: Office Supplies | BM11: Furniture | BN11: Office Supplies | BO11: Technology | BP11: Furniture | BQ11: Furniture | BR11: Technology | BS11: Office Supplies | BT11: Office Supplies | BU11: Furniture | BV11: Technology | BW11: Furniture | BX11: Office Supplies | BY11: Office Supplies | BZ11: Furniture | CA11: Office Supplies | CB11: Technology | CC11: Furniture | CD11: Technology | CE11: Furniture | CF11: Technology | CG11: Technology | CH11: Furniture | CI11: Office Supplies | CJ11: Furniture | CK11: Office Supplies | CL11: Office Supplies | CM11: Office Supplies | CN11: Furniture | CO11: Office Supplies | CP11: Technology | CQ11: Furniture | CR11: Technology | CS11: Furniture | CT11: Furniture | CU11: Furniture | CV11: Furniture | CW11: Office Supplies | CX11: Technology | CY11: Office Supplies | CZ11: Office Supplies | DA11: Technology | DB11: Furniture | DC11: Office Supplies | DD11: Office Supplies | DE11: Technology | DF11: Furniture | DG11: Technology | DH11: Office Supplies | DI11: Office Supplies | DJ11: Office Supplies | DK11: Office Supplies | DL11: Technology | DM11: Furniture | DN11: Furniture | DO11: Technology | DP11: Furniture | DQ11: Furniture | DR11: Office Supplies | DS11: Furniture | DT11: Technology | DU11: Furniture | DV11: Technology | DW11: Technology | DX11: Office Supplies | DY11: Furniture | DZ11: Office Supplies | EA11: Technology | EB11: Technology | EC11: Technology | ED11: Office Supplies | EE11: Furniture | EF11: Office Supplies | EG11: Furniture | EH11: Furniture | EI11: Office Supplies | EJ11: Technology | EK11: Furniture | EL11: Office Supplies | EM11: Furniture | EN11: Technology | EO11: Furniture | EP11: Office Supplies | EQ11: Office Supplies | ER11: Furniture | ES11: Furniture | ET11: Office Supplies | EU11: Technology | EV11: Technology | EW11: Technology | EX11: Office Supplies | EY11: Technology | EZ11: Furniture | FA11: Office Supplies | FB11: Furniture | FC11: Technology | FD11: Office Supplies | FE11: Technology | FF11: Technology | FG11: Technology | FH11: Office Supplies | FI11: Furniture | FJ11: Office Supplies | FK11: Technology | FL11: Office Supplies | FM11: Furniture | FN11: Furniture | FO11: Furniture | FP11: Office Supplies | FQ11: Office Supplies | FR11: Furniture | FS11: Furniture | FT11: Furniture | FU11: Furniture | FV11: Office Supplies | FW11: Office Supplies | FX11: Office Supplies | FY11: Office Supplies | FZ11: Furniture | GA11: Technology | GB11: Technology | GC11: Technology | GD11: Office Supplies | GE11: Furniture | GF11: Furniture | GG11: Technology | GH11: Office Supplies | GI11: Furniture | GJ11: Technology | GK11: Office Supplies | GL11: Office Supplies | GM11: Office Supplies | GN11: Furniture | GO11: Technology | GP11: Technology | GQ11: Office Supplies | GR11: Furniture | GS11: Furniture
A12: Sub-Category | B12: Storage | C12: Storage | D12: Tables | E12: Tables | F12: Storage | G12: Chairs | H12: Chairs | I12: Tables | J12: Tables | K12: Binders | L12: Chairs | M12: Phones | N12: Phones | O12: Tables | P12: Laptops | Q12: Phones | R12: Laptops | S12: Storage | T12: Storage | U12: Phones | V12: Chairs | W12: Chairs | X12: Laptops | Y12: Chairs | Z12: Storage | AA12: Laptops | AB12: Tables | AC12: Phones | AD12: Laptops | AE12: Phones | AF12: Phones | AG12: Phones | AH12: Tables | AI12: Phones | AJ12: Tables | AK12: Phones | AL12: Storage | AM12: Storage | AN12: Phones | AO12: Storage | AP12: Chairs | AQ12: Binders | AR12: Chairs | AS12: Chairs | AT12: Chairs | AU12: Tables | AV12: Tables | AW12: Phones | AX12: Chairs | AY12: Tables | AZ12: Laptops | BA12: Phones | BB12: Tables | BC12: Phones | BD12: Phones | BE12: Chairs | BF12: Laptops | BG12: Binders | BH12: Tables | BI12: Storage | BJ12: Chairs | BK12: Laptops | BL12: Chairs | BM12: Tables | BN12: Chairs | BO12: Binders | BP12: Binders | BQ12: Chairs | BR12: Storage | BS12: Phones | BT12: Binders | BU12: Binders | BV12: Laptops | BW12: Laptops | BX12: Binders | BY12: Tables | BZ12: Storage | CA12: Tables | CB12: Binders | CC12: Storage | CD12: Phones | CE12: Chairs | CF12: Storage | CG12: Chairs | CH12: Laptops | CI12: Binders | CJ12: Phones | CK12: Storage | CL12: Tables | CM12: Laptops | CN12: Chairs | CO12: Storage | CP12: Binders | CQ12: Phones | CR12: Tables | CS12: Laptops | CT12: Laptops | CU12: Tables | CV12: Storage | CW12: Tables | CX12: Storage | CY12: Storage | CZ12: Laptops | DA12: Binders | DB12: Tables | DC12: Chairs | DD12: Binders | DE12: Laptops | DF12: Laptops | DG12: Chairs | DH12: Phones | DI12: Binders | DJ12: Binders | DK12: Chairs | DL12: Phones | DM12: Laptops | DN12: Storage | DO12: Tables | DP12: Binders | DQ12: Phones | DR12: Tables | DS12: Tables | DT12: Laptops | DU12: Tables | DV12: Binders | DW12: Tables | DX12: Laptops | DY12: Chairs | DZ12: Storage | EA12: Phones | EB12: Phones | EC12: Tables | ED12: Binders | EE12: Binders | EF12: Storage | EG12: Binders | EH12: Binders | EI12: Chairs | EJ12: Storage | EK12: Storage | EL12: Phones | EM12: Storage | EN12: Storage | EO12: Binders | EP12: Storage | EQ12: Binders | ER12: Storage | ES12: Tables | ET12: Binders | EU12: Binders | EV12: Binders | EW12: Phones | EX12: Chairs | EY12: Storage | EZ12: Storage | FA12: Chairs | FB12: Chairs | FC12: Binders | FD12: Phones | FE12: Chairs | FF12: Binders | FG12: Chairs | FH12: Phones | FI12: Laptops | FJ12: Laptops | FK12: Laptops | FL12: Binders | FM12: Chairs | FN12: Storage | FO12: Phones | FP12: Phones | FQ12: Chairs | FR12: Storage | FS12: Chairs | FT12: Phones | FU12: Laptops | FV12: Storage | FW12: Chairs | FX12: Chairs | FY12: Laptops | FZ12: Chairs | GA12: Laptops | GB12: Storage | GC12: Binders | GD12: Storage | GE12: Chairs | GF12: Binders | GG12: Laptops | GH12: Tables | GI12: Storage | GJ12: Phones | GK12: Phones | GL12: Chairs | GM12: Laptops | GN12: Tables | GO12: Storage | GP12: Laptops | GQ12: Binders | GR12: Laptops | GS12: Phones
A13: Customer Segment | B13: Corporate | C13: Home Office | D13: Home Office | E13: Corporate | F13: Home Office | G13: Home Office | H13: Corporate | I13: Corporate | J13: Home Office | K13: Home Office | L13: Home Office | M13: Home Office | N13: Home Office | O13: Consumer | P13: Consumer | Q13: Consumer | R13: Home Office | S13: Consumer | T13: Home Office | U13: Corporate | V13: Consumer | W13: Corporate | X13: Consumer | Y13: Consumer | Z13: Home Office | AA13: Corporate | AB13: Home Office | AC13: Consumer | AD13: Corporate | AE13: Corporate | AF13: Consumer | AG13: Corporate | AH13: Home Office | AI13: Consumer | AJ13: Home Office | AK13: Corporate | AL13: Corporate | AM13: Corporate | AN13: Home Office | AO13: Home Office | AP13: Consumer | AQ13: Corporate | AR13: Corporate | AS13: Corporate | AT13: Home Office | AU13: Corporate | AV13: Corporate | AW13: Consumer | AX13: Consumer | AY13: Home Office | AZ13: Consumer | BA13: Home Office | BB13: Consumer | BC13: Consumer | BD13: Consumer | BE13: Consumer | BF13: Corporate | BG13: Corporate | BH13: Corporate | BI13: Corporate | BJ13: Consumer | BK13: Corporate | BL13: Corporate | BM13: Consumer | BN13: Home Office | BO13: Consumer | BP13: Consumer | BQ13: Home Office | BR13: Corporate | BS13: Corporate | BT13: Consumer | BU13: Corporate | BV13: Consumer | BW13: Consumer | BX13: Corporate | BY13: Corporate | BZ13: Corporate | CA13: Consumer | CB13: Corporate | CC13: Corporate | CD13: Consumer | CE13: Corporate | CF13: Home Office | CG13: Home Office | CH13: Home Office | CI13: Corporate | CJ13: Corporate | CK13: Corporate | CL13: Home Office | CM13: Corporate | CN13: Consumer | CO13: Home Office | CP13: Home Office | CQ13: Corporate | CR13: Consumer | CS13: Consumer | CT13: Home Office | CU13: Corporate | CV13: Consumer | CW13: Consumer | CX13: Consumer | CY13: Corporate | CZ13: Home Office | DA13: Corporate | DB13: Home Office | DC13: Corporate | DD13: Home Office | DE13: Corporate | DF13: Consumer | DG13: Home Office | DH13: Consumer | DI13: Corporate | DJ13: Consumer | DK13: Consumer | DL13: Corporate | DM13: Home Office | DN13: Corporate | DO13: Corporate | DP13: Corporate | DQ13: Corporate | DR13: Corporate | DS13: Corporate | DT13: Home Office | DU13: Corporate | DV13: Home Office | DW13: Consumer | DX13: Consumer | DY13: Consumer | DZ13: Consumer | EA13: Corporate | EB13: Home Office | EC13: Consumer | ED13: Consumer | EE13: Consumer | EF13: Consumer | EG13: Corporate | EH13: Corporate | EI13: Corporate | EJ13: Consumer | EK13: Corporate | EL13: Consumer | EM13: Corporate | EN13: Home Office | EO13: Home Office | EP13: Corporate | EQ13: Corporate | ER13: Consumer | ES13: Corporate | ET13: Home Office | EU13: Corporate | EV13: Consumer | EW13: Corporate | EX13: Consumer | EY13: Consumer | EZ13: Consumer | FA13: Consumer | FB13: Consumer | FC13: Home Office | FD13: Consumer | FE13: Consumer | FF13: Home Office | FG13: Corporate | FH13: Home Office | FI13: Consumer | FJ13: Home Office | FK13: Home Office | FL13: Corporate | FM13: Consumer | FN13: Corporate | FO13: Home Office | FP13: Consumer | FQ13: Home Office | FR13: Consumer | FS13: Home Office | FT13: Home Office | FU13: Corporate | FV13: Corporate | FW13: Corporate | FX13: Corporate | FY13: Corporate | FZ13: Corporate | GA13: Corporate | GB13: Home Office | GC13: Home Office | GD13: Consumer | GE13: Home Office | GF13: Consumer | GG13: Home Office | GH13: Consumer | GI13: Consumer | GJ13: Consumer | GK13: Corporate | GL13: Consumer | GM13: Corporate | GN13: Consumer | GO13: Consumer | GP13: Corporate | GQ13: Home Office | GR13: Home Office | GS13: Corporate
A14: Sales | B14: 20012.71 | C14: 32526.73 | D14: 4927.51 | E14: 38088.83 | F14: 19018.79 | G14: 13800.67 | H14: 31318.96 | I14: 10853.73 | J14: 6540.32 | K14: 10918.37 | L14: 27163.21 | M14: 4746.18 | N14: 18491.32 | O14: 10033.93 | P14: 22190.58 | Q14: 6220.59 | R14: 31139.48 | S14: 37017.37 | T14: 13318.88 | U14: 14695.56 | V14: 24244.94 | W14: 29761.68 | X14: 3084.33 | Y14: 27251.31 | Z14: 32718.53 | AA14: 31866.83 | AB14: 17993.17 | AC14: 33052.6 | AD14: 22245.41 | AE14: 8119.62 | AF14: 12000.88 | AG14: 24035.25 | AH14: 22457.01 | AI14: 32245 | AJ14: 28823.82 | AK14: 9151.96 | AL14: 16377.54 | AM14: 31300.51 | AN14: 18758.23 | AO14: 9621.19 | AP14: 37534.11 | AQ14: 18403.76 | AR14: 12902.1 | AS14: 20841.32 | AT14: 12596 | AU14: 11399.04 | AV14: 26732.05 | AW14: 31973.15 | AX14: 16826.2 | AY14: 7108.85 | AZ14: 19451.18 | BA14: 16542.75 | BB14: 17879.88 | BC14: 10203.14 | BD14: 30968.22 | BE14: 8727.32 | BF14: 2314.94 | BG14: 28244.45 | BH14: 29906.04 | BI14: 10159.37 | BJ14: 7597.51 | BK14: 23556.83 | BL14: 36849.51 | BM14: 10756.15 | BN14: 21968.16 | BO14: 11163.63 | BP14: 29872.59 | BQ14: 19110.18 | BR14: 15655.09 | BS14: 26520.71 | BT14: 21631.65 | BU14: 8685.05 | BV14: 17115.52 | BW14: 38294.55 | BX14: 32204.5 | BY14: 20874.66 | BZ14: 26690.16 | CA14: 6380.96 | CB14: 16997.18 | CC14: 35876.8 | CD14: 8174.32 | CE14: 39291.32 | CF14: 34045.95 | CG14: 27696.22 | CH14: 15446.07 | CI14: 4409.44 | CJ14: 12351.61 | CK14: 29847.06 | CL14: 17327.56 | CM14: 32273.13 | CN14: 9259.22 | CO14: 33090.85 | CP14: 34516.37 | CQ14: 29110.13 | CR14: 8797.35 | CS14: 9537.34 | CT14: 3320.34 | CU14: 2811.01 | CV14: 29771.53 | CW14: 20067.45 | CX14: 30651.24 | CY14: 11883.65 | CZ14: 14334.46 | DA14: 35872.38 | DB14: 39897.43 | DC14: 4788.83 | DD14: 31346.68 | DE14: 22601.02 | DF14: 978.31 | DG14: 24968.77 | DH14: 11773.18 | DI14: 14542.07 | DJ14: 38795.73 | DK14: 29912.97 | DL14: 2937.25 | DM14: 27494.25 | DN14: 1309.43 | DO14: 35538.8 | DP14: 24189.95 | DQ14: 25528.2 | DR14: 1444.79 | DS14: 4084.41 | DT14: 21425.19 | DU14: 15764 | DV14: 32877.18 | DW14: 11931.71 | DX14: 16466.89 | DY14: 5503.95 | DZ14: 20512.54 | EA14: 38236.85 | EB14: 11223.16 | EC14: 31800.6 | ED14: 7227.08 | EE14: 35527.4 | EF14: 20895.22 | EG14: 5731.68 | EH14: 31481.71 | EI14: 35593.4 | EJ14: 6486.4 | EK14: 5402.7 | EL14: 10654.43 | EM14: 20985.98 | EN14: 38044.33 | EO14: 34535.49 | EP14: 13525.34 | EQ14: 2260.59 | ER14: 24151.75 | ES14: 23330.67 | ET14: 10268.28 | EU14: 24459.58 | EV14: 39278.5 | EW14: 6459.97 | EX14: 13140.25 | EY14: 34039 | EZ14: 7039.66 | FA14: 5847.74 | FB14: 7543.26 | FC14: 30972.14 | FD14: 5795.26 | FE14: 4372.08 | FF14: 25376.72 | FG14: 30859.74 | FH14: 30448.78 | FI14: 17777.63 | FJ14: 36730.73 | FK14: 6714.31 | FL14: 18107.64 | FM14: 15276.06 | FN14: 22210.49 | FO14: 8375.88 | FP14: 6567.22 | FQ14: 39347.65 | FR14: 12643.35 | FS14: 20388.31 | FT14: 36717.72 | FU14: 12663.95 | FV14: 15170.56 | FW14: 22875.68 | FX14: 3468.05 | FY14: 1716.38 | FZ14: 25604.14 | GA14: 15338.55 | GB14: 3916.45 | GC14: 12036.2 | GD14: 27983.49 | GE14: 30576.58 | GF14: 20611.53 | GG14: 9453.95 | GH14: 33708.24 | GI14: 8941.57 | GJ14: 30471.09 | GK14: 6806.38 | GL14: 37446.24 | GM14: 31116.13 | GN14: 20448.6 | GO14: 17819.51 | GP14: 23260.65 | GQ14: 26715.68 | GR14: 22669 | GS14: 28076.03
A15: Quantity | B15: 6 | C15: 6 | D15: 1 | E15: 2 | F15: 2 | G15: 6 | H15: 9 | I15: 10 | J15: 3 | K15: 4 | L15: 10 | M15: 11 | N15: 9 | O15: 1 | P15: 6 | Q15: 11 | R15: 5 | S15: 1 | T15: 3 | U15: 3 | V15: 9 | W15: 10 | X15: 4 | Y15: 10 | Z15: 7 | AA15: 1 | AB15: 1 | AC15: 10 | AD15: 10 | AE15: 1 | AF15: 6 | AG15: 11 | AH15: 7 | AI15: 4 | AJ15: 6 | AK15: 3 | AL15: 10 | AM15: 4 | AN15: 5 | AO15: 6 | AP15: 1 | AQ15: 6 | AR15: 8 | AS15: 6 | AT15: 7 | AU15: 8 | AV15: 6 | AW15: 4 | AX15: 4 | AY15: 10 | AZ15: 11 | BA15: 7 | BB15: 10 | BC15: 5 | BD15: 8 | BE15: 3 | BF15: 8 | BG15: 9 | BH15: 1 | BI15: 11 | BJ15: 3 | BK15: 9 | BL15: 3 | BM15: 3 | BN15: 1 | BO15: 8 | BP15: 8 | BQ15: 4 | BR15: 6 | BS15: 11 | BT15: 2 | BU15: 3 | BV15: 2 | BW15: 2 | BX15: 5 | BY15: 10 | BZ15: 10 | CA15: 6 | CB15: 4 | CC15: 4 | CD15: 1 | CE15: 3 | CF15: 11 | CG15: 8 | CH15: 3 | CI15: 4 | CJ15: 11 | CK15: 5 | CL15: 8 | CM15: 10 | CN15: 9 | CO15: 1 | CP15: 10 | CQ15: 3 | CR15: 2 | CS15: 2 | CT15: 11 | CU15: 10 | CV15: 11 | CW15: 3 | CX15: 8 | CY15: 3 | CZ15: 1 | DA15: 7 | DB15: 11 | DC15: 3 | DD15: 1 | DE15: 7 | DF15: 1 | DG15: 9 | DH15: 3 | DI15: 1 | DJ15: 1 | DK15: 7 | DL15: 10 | DM15: 1 | DN15: 4 | DO15: 6 | DP15: 8 | DQ15: 7 | DR15: 11 | DS15: 7 | DT15: 10 | DU15: 4 | DV15: 7 | DW15: 2 | DX15: 4 | DY15: 10 | DZ15: 7 | EA15: 7 | EB15: 7 | EC15: 7 | ED15: 1 | EE15: 7 | EF15: 1 | EG15: 7 | EH15: 6 | EI15: 7 | EJ15: 11 | EK15: 11 | EL15: 4 | EM15: 2 | EN15: 5 | EO15: 6 | EP15: 10 | EQ15: 5 | ER15: 3 | ES15: 9 | ET15: 11 | EU15: 10 | EV15: 10 | EW15: 1 | EX15: 10 | EY15: 4 | EZ15: 2 | FA15: 2 | FB15: 11 | FC15: 6 | FD15: 2 | FE15: 1 | FF15: 9 | FG15: 4 | FH15: 2 | FI15: 7 | FJ15: 11 | FK15: 3 | FL15: 10 | FM15: 11 | FN15: 9 | FO15: 6 | FP15: 3 | FQ15: 3 | FR15: 4 | FS15: 5 | FT15: 9 | FU15: 8 | FV15: 1 | FW15: 6 | FX15: 7 | FY15: 3 | FZ15: 6 | GA15: 9 | GB15: 9 | GC15: 11 | GD15: 5 | GE15: 11 | GF15: 4 | GG15: 4 | GH15: 11 | GI15: 6 | GJ15: 2 | GK15: 2 | GL15: 5 | GM15: 1 | GN15: 7 | GO15: 10 | GP15: 7 | GQ15: 2 | GR15: 3 | GS15: 2
A16: Discount | B16: 0.05 | C16: 0.17 | D16: 0.12 | E16: 0.23 | F16: 0.22 | G16: 0.09 | H16: 0.1 | I16: 0.23 | J16: 0.24 | K16: 0.2 | L16: 0.02 | M16: 0.01 | N16: 0.15 | O16: 0.19 | P16: 0.18 | Q16: 0.2 | R16: 0.04 | S16: 0 | T16: 0.14 | U16: 0.22 | V16: 0.06 | W16: 0.05 | X16: 0.22 | Y16: 0.09 | Z16: 0.09 | AA16: 0.15 | AB16: 0.07 | AC16: 0.23 | AD16: 0.05 | AE16: 0.01 | AF16: 0.11 | AG16: 0.15 | AH16: 0.07 | AI16: 0.19 | AJ16: 0.02 | AK16: 0.08 | AL16: 0.11 | AM16: 0.24 | AN16: 0.03 | AO16: 0.04 | AP16: 0.05 | AQ16: 0.19 | AR16: 0.07 | AS16: 0.08 | AT16: 0.14 | AU16: 0.1 | AV16: 0.15 | AW16: 0.13 | AX16: 0.18 | AY16: 0.25 | AZ16: 0.09 | BA16: 0.05 | BB16: 0.04 | BC16: 0.1 | BD16: 0.23 | BE16: 0.05 | BF16: 0.09 | BG16: 0.22 | BH16: 0.22 | BI16: 0.15 | BJ16: 0.19 | BK16: 0.22 | BL16: 0.02 | BM16: 0.1 | BN16: 0.23 | BO16: 0.13 | BP16: 0.05 | BQ16: 0.12 | BR16: 0.2 | BS16: 0.24 | BT16: 0.21 | BU16: 0.13 | BV16: 0.17 | BW16: 0.03 | BX16: 0.24 | BY16: 0.16 | BZ16: 0 | CA16: 0.22 | CB16: 0.03 | CC16: 0.12 | CD16: 0.06 | CE16: 0.08 | CF16: 0.17 | CG16: 0 | CH16: 0.13 | CI16: 0.05 | CJ16: 0.22 | CK16: 0.08 | CL16: 0.09 | CM16: 0.1 | CN16: 0.2 | CO16: 0.13 | CP16: 0.18 | CQ16: 0.19 | CR16: 0.08 | CS16: 0.05 | CT16: 0.12 | CU16: 0.14 | CV16: 0.01 | CW16: 0.02 | CX16: 0.17 | CY16: 0.24 | CZ16: 0.23 | DA16: 0.07 | DB16: 0.21 | DC16: 0.15 | DD16: 0.17 | DE16: 0.21 | DF16: 0.1 | DG16: 0.21 | DH16: 0.2 | DI16: 0.03 | DJ16: 0.15 | DK16: 0.11 | DL16: 0.21 | DM16: 0.07 | DN16: 0.04 | DO16: 0.08 | DP16: 0.24 | DQ16: 0.03 | DR16: 0.2 | DS16: 0.05 | DT16: 0.05 | DU16: 0.22 | DV16: 0.15 | DW16: 0.05 | DX16: 0.05 | DY16: 0.14 | DZ16: 0.07 | EA16: 0.11 | EB16: 0.21 | EC16: 0.12 | ED16: 0.03 | EE16: 0.13 | EF16: 0.24 | EG16: 0.2 | EH16: 0.2 | EI16: 0.14 | EJ16: 0.23 | EK16: 0.18 | EL16: 0.02 | EM16: 0.17 | EN16: 0.12 | EO16: 0.05 | EP16: 0 | EQ16: 0.04 | ER16: 0.19 | ES16: 0.06 | ET16: 0.11 | EU16: 0.17 | EV16: 0.23 | EW16: 0.11 | EX16: 0.17 | EY16: 0.18 | EZ16: 0.02 | FA16: 0.11 | FB16: 0.02 | FC16: 0.2 | FD16: 0.08 | FE16: 0.23 | FF16: 0.24 | FG16: 0.23 | FH16: 0.22 | FI16: 0.21 | FJ16: 0.02 | FK16: 0.09 | FL16: 0.25 | FM16: 0.22 | FN16: 0.23 | FO16: 0.15 | FP16: 0.13 | FQ16: 0.02 | FR16: 0.18 | FS16: 0.14 | FT16: 0.24 | FU16: 0.03 | FV16: 0.1 | FW16: 0.11 | FX16: 0.1 | FY16: 0.02 | FZ16: 0.18 | GA16: 0.15 | GB16: 0.16 | GC16: 0.02 | GD16: 0.06 | GE16: 0.07 | GF16: 0.02 | GG16: 0.18 | GH16: 0.06 | GI16: 0.14 | GJ16: 0.18 | GK16: 0.05 | GL16: 0.22 | GM16: 0.14 | GN16: 0.07 | GO16: 0.17 | GP16: 0.22 | GQ16: 0.02 | GR16: 0.22 | GS16: 0.03
A17: Cost | B17: 15106.38 | C17: 23572.63 | D17: 4078.38 | E17: 27212.31 | F17: 15518.61 | G17: 9746.46 | H17: 24472.12 | I17: 8411.58 | J17: 5549.91 | K17: 6613.21 | L17: 17088.96 | M17: 3260.06 | N17: 14371.46 | O17: 5696.45 | P17: 14384.24 | Q17: 5015.54 | R17: 21774.79 | S17: 24882.43 | T17: 11298.67 | U17: 12235.62 | V17: 17024.38 | W17: 16801.98 | X17: 2000.65 | Y17: 22616.54 | Z17: 20796.44 | AA17: 25409.8 | AB17: 11948.81 | AC17: 24651.86 | AD17: 14506.28 | AE17: 4688.53 | AF17: 7087.45 | AG17: 18116.22 | AH17: 15249.75 | AI17: 21216.16 | AJ17: 22649.79 | AK17: 6459.57 | AL17: 11306.24 | AM17: 25571.35 | AN17: 12412.27 | AO17: 7224.21 | AP17: 21732.18 | AQ17: 12801.22 | AR17: 8553.74 | AS17: 13777.95 | AT17: 10471.29 | AU17: 8663.89 | AV17: 15217.58 | AW17: 25648.49 | AX17: 13591.84 | AY17: 4080.36 | AZ17: 13054.03 | BA17: 9884.32 | BB17: 11687.07 | BC17: 5613.71 | BD17: 22751.18 | BE17: 5351.07 | BF17: 1843.25 | BG17: 23621.32 | BH17: 18659.68 | BI17: 8470.97 | BJ17: 5790.12 | BK17: 18552.82 | BL17: 27203.08 | BM17: 8141.96 | BN17: 16073.03 | BO17: 8460.58 | BP17: 18037.88 | BQ17: 13754.28 | BR17: 10527.31 | BS17: 14648.13 | BT17: 15498.97 | BU17: 6897.54 | BV17: 9765.33 | BW17: 24985.72 | BX17: 25574.07 | BY17: 12565.75 | BZ17: 19967.21 | CA17: 5001.17 | CB17: 11085.73 | CC17: 20768.56 | CD17: 4805.23 | CE17: 23554.76 | CF17: 25857.56 | CG17: 23532.89 | CH17: 12287.36 | CI17: 3287.89 | CJ17: 8639.69 | CK17: 24314.77 | CL17: 13911.01 | CM17: 22399.82 | CN17: 7330.44 | CO17: 26043.93 | CP17: 25759.09 | CQ17: 17239.07 | CR17: 5457.25 | CS17: 6044.3 | CT17: 2748.49 | CU17: 2236.52 | CV17: 22494.94 | CW17: 13974.28 | CX17: 21765.95 | CY17: 6733.55 | CZ17: 10207.64 | DA17: 20610.95 | DB17: 28479.01 | DC17: 3311.5 | DD17: 23333.42 | DE17: 13583.32 | DF17: 591.8 | DG17: 13943.8 | DH17: 9982.12 | DI17: 10678.86 | DJ17: 25016.65 | DK17: 20511.25 | DL17: 1854.85 | DM17: 17865.17 | DN17: 1086.93 | DO17: 24972.52 | DP17: 16674.18 | DQ17: 16247.13 | DR17: 1077.07 | DS17: 2661.2 | DT17: 12501.28 | DU17: 9669.64 | DV17: 25926.92 | DW17: 8202.12 | DX17: 13937.26 | DY17: 3893.3 | DZ17: 13692.09 | EA17: 25913.8 | EB17: 9450.8 | EC17: 24936.36 | ED17: 4337.78 | EE17: 25271.85 | EF17: 15886.03 | EG17: 4690.6 | EH17: 26334.01 | EI17: 29019.23 | EJ17: 5031.02 | EK17: 4443.21 | EL17: 7495.64 | EM17: 12281.31 | EN17: 25566.02 | EO17: 29204.15 | EP17: 8211.54 | EQ17: 1822.12 | ER17: 16810.26 | ES17: 13537.59 | ET17: 8538.12 | EU17: 13891.4 | EV17: 31008.22 | EW17: 5480.52 | EX17: 8607.12 | EY17: 22468.16 | EZ17: 4511.69 | FA17: 3565.82 | FB17: 5732.84 | FC17: 17149.44 | FD17: 3255.9 | FE17: 2650.34 | FF17: 19703.29 | FG17: 22817.03 | FH17: 24217.46 | FI17: 14030.24 | FJ17: 20670.19 | FK17: 5570.71 | FL17: 14154.85 | FM17: 12810.4 | FN17: 13073.91 | FO17: 5913.67 | FP17: 4148.12 | FQ17: 26174.9 | FR17: 9886.14 | FS17: 13845.89 | FT17: 27041.42 | FU17: 10041.31 | FV17: 10604.87 | FW17: 13596.47 | FX17: 2056.44 | FY17: 1348.25 | FZ17: 16578.2 | GA17: 11260.6 | GB17: 3155.59 | GC17: 8970.93 | GD17: 21873.82 | GE17: 24809.83 | GF17: 13606.49 | GG17: 5443.7 | GH17: 20279.15 | GI17: 6372.05 | GJ17: 21188.31 | GK17: 4987.73 | GL17: 28628.36 | GM17: 24023.38 | GN17: 11707.12 | GO17: 11865.31 | GP17: 12908.99 | GQ17: 19697.01 | GR17: 18119.66 | GS17: 16368.5
A18: Profit | B18: 4906.33 | C18: 8954.1 | D18: 849.13 | E18: 10876.52 | F18: 3500.18 | G18: 4054.21 | H18: 6846.84 | I18: 2442.15 | J18: 990.41 | K18: 4305.16 | L18: 10074.25 | M18: 1486.12 | N18: 4119.86 | O18: 4337.48 | P18: 7806.34 | Q18: 1205.05 | R18: 9364.69 | S18: 12134.94 | T18: 2020.21 | U18: 2459.94 | V18: 7220.56 | W18: 12959.7 | X18: 1083.68 | Y18: 4634.77 | Z18: 11922.09 | AA18: 6457.03 | AB18: 6044.36 | AC18: 8400.74 | AD18: 7739.13 | AE18: 3431.09 | AF18: 4913.43 | AG18: 5919.03 | AH18: 7207.26 | AI18: 11028.84 | AJ18: 6174.03 | AK18: 2692.39 | AL18: 5071.3 | AM18: 5729.16 | AN18: 6345.96 | AO18: 2396.98 | AP18: 15801.93 | AQ18: 5602.54 | AR18: 4348.36 | AS18: 7063.37 | AT18: 2124.71 | AU18: 2735.15 | AV18: 11514.47 | AW18: 6324.66 | AX18: 3234.36 | AY18: 3028.49 | AZ18: 6397.15 | BA18: 6658.43 | BB18: 6192.81 | BC18: 4589.43 | BD18: 8217.04 | BE18: 3376.25 | BF18: 471.69 | BG18: 4623.13 | BH18: 11246.36 | BI18: 1688.4 | BJ18: 1807.39 | BK18: 5004.01 | BL18: 9646.43 | BM18: 2614.19 | BN18: 5895.13 | BO18: 2703.05 | BP18: 11834.71 | BQ18: 5355.9 | BR18: 5127.78 | BS18: 11872.58 | BT18: 6132.68 | BU18: 1787.51 | BV18: 7350.19 | BW18: 13308.83 | BX18: 6630.43 | BY18: 8308.91 | BZ18: 6722.95 | CA18: 1379.79 | CB18: 5911.45 | CC18: 15108.24 | CD18: 3369.09 | CE18: 15736.56 | CF18: 8188.39 | CG18: 4163.33 | CH18: 3158.71 | CI18: 1121.55 | CJ18: 3711.92 | CK18: 5532.29 | CL18: 3416.55 | CM18: 9873.31 | CN18: 1928.78 | CO18: 7046.92 | CP18: 8757.28 | CQ18: 11871.06 | CR18: 3340.1 | CS18: 3493.04 | CT18: 571.85 | CU18: 574.49 | CV18: 7276.59 | CW18: 6093.17 | CX18: 8885.29 | CY18: 5150.1 | CZ18: 4126.82 | DA18: 15261.43 | DB18: 11418.42 | DC18: 1477.33 | DD18: 8013.26 | DE18: 9017.7 | DF18: 386.51 | DG18: 11024.97 | DH18: 1791.06 | DI18: 3863.21 | DJ18: 13779.08 | DK18: 9401.72 | DL18: 1082.4 | DM18: 9629.08 | DN18: 222.5 | DO18: 10566.28 | DP18: 7515.77 | DQ18: 9281.07 | DR18: 367.72 | DS18: 1423.21 | DT18: 8923.91 | DU18: 6094.36 | DV18: 6950.26 | DW18: 3729.59 | DX18: 2529.63 | DY18: 1610.65 | DZ18: 6820.45 | EA18: 12323.05 | EB18: 1772.36 | EC18: 6864.24 | ED18: 2889.3 | EE18: 10255.55 | EF18: 5009.19 | EG18: 1041.08 | EH18: 5147.7 | EI18: 6574.17 | EJ18: 1455.38 | EK18: 959.49 | EL18: 3158.79 | EM18: 8704.67 | EN18: 12478.31 | EO18: 5331.34 | EP18: 5313.8 | EQ18: 438.47 | ER18: 7341.49 | ES18: 9793.08 | ET18: 1730.16 | EU18: 10568.18 | EV18: 8270.28 | EW18: 979.45 | EX18: 4533.13 | EY18: 11570.84 | EZ18: 2527.97 | FA18: 2281.92 | FB18: 1810.42 | FC18: 13822.7 | FD18: 2539.36 | FE18: 1721.74 | FF18: 5673.43 | FG18: 8042.71 | FH18: 6231.32 | FI18: 3747.39 | FJ18: 16060.54 | FK18: 1143.6 | FL18: 3952.79 | FM18: 2465.66 | FN18: 9136.58 | FO18: 2462.21 | FP18: 2419.1 | FQ18: 13172.75 | FR18: 2757.21 | FS18: 6542.42 | FT18: 9676.3 | FU18: 2622.64 | FV18: 4565.69 | FW18: 9279.21 | FX18: 1411.61 | FY18: 368.13 | FZ18: 9025.94 | GA18: 4077.95 | GB18: 760.86 | GC18: 3065.27 | GD18: 6109.67 | GE18: 5766.75 | GF18: 7005.04 | GG18: 4010.25 | GH18: 13429.09 | GI18: 2569.52 | GJ18: 9282.78 | GK18: 1818.65 | GL18: 8817.88 | GM18: 7092.75 | GN18: 8741.48 | GO18: 5954.2 | GP18: 10351.66 | GQ18: 7018.67 | GR18: 4549.34 | GS18: 11707.53
A19: Unit Price | B19: =B14/B15 -> 3335.4517 | C19: =C14/C15 -> 5421.1217 | D19: =D14/D15 -> 4927.51 | E19: =E14/E15 -> 19044.415 | F19: =F14/F15 -> 9509.395 | G19: =G14/G15 -> 2300.1117 | H19: =H14/H15 -> 3479.8844 | I19: =I14/I15 -> 1085.373 | ... GS19: =GS14/GS15 -> 14038.015
A22: Order ID | B22: Sales | C22: Quantity | D22: Profit
A23: ORD2004 | B23: =HLOOKUP(A23,$A$5:$GS$19,10,0) -> 19018.79 | C23: =HLOOKUP(A23,A5:GS19,11,0) -> 2 | D23: =HLOOKUP(A23,A5:GS19,14,0) -> 3500.18

Sheet Count & Sum
A1: Order ID | B1: Sales | D1: Category | E1: Total Sales | G1: Customer Segment | H1: Total Quantity
A2: ORD2000 | B2: =SUMIF(Data!A1:A201,'Count & Sum'!A2,Data!J1:J201) -> 20012.71 | D2: Furniture | E2: =SUMIF(Data!G2:G201, D2,Data!J2:J201) -> 1449623.5 | G2: Corporate | H2: =SUMIF(Data!I2:I201,'Count & Sum'!G2,Data!K2:K201) -> 482 | J2: Calculated total sales per individual Order ID utilizing the SUMIF function to aggregate transactional data.
A3: ORD2001 | B3: =SUMIF(Data!A2:A202,'Count & Sum'!A3,Data!J2:J202) -> 32526.73 | D3: Office Supplies | E3: =SUMIF(Data!G3:G202, D3,Data!J3:J202) -> 1270454.2 | G3: Home Office | H3: =SUMIF(Data!I3:I202,'Count & Sum'!G3,Data!K3:K202) -> 336 | J3: Calculated total sales by category using SUMIF.
A4: ORD2002 | B4: =SUMIF(Data!A3:A203,'Count & Sum'!A4,Data!J3:J203) -> 4927.51 | D4: Technology | E4: =SUMIF(Data!G4:G203, D4,Data!J4:J203) -> 1249818 | G4: Consumer | H4: =SUMIF(Data!I4:I203,'Count & Sum'!G4,Data!K4:K203) -> 364 | J4: Calculated total profit by sub-category using SUMIF.
A5: ORD2003 | B5: =SUMIF(Data!A4:A204,'Count & Sum'!A5,Data!J4:J204) -> 38088.83 | J5: Counted cells using COUNT, COUNTA, COUNTBLANK, COUNTIF, and COUNTIFS.
A6: ORD2004 | B6: =SUMIF(Data!A5:A205,'Count & Sum'!A6,Data!J5:J205) -> 19018.79 | D6: Sub-Category | E6: Total Profit | G6: Month | H6: Total Sales | J6: Analyzed the cost for the South region in the UK and calculated profit for Home Office furniture (e.g., chairs).
A7: ORD2005 | B7: =SUMIF(Data!A6:A206,'Count & Sum'!A7,Data!J6:J206) -> 13800.67 | D7: Storage | E7: =SUMIF(Data!H2:H201,'Count & Sum'!D7,Data!N2:N201) -> 221620.06 | G7: June | H7: =SUMIF(Data!D2:D201,'Count & Sum'!G7,Data!J2:J201) -> 230989.06 | J7: Calculated total quantity by customer segment (Corporate, Home Office, and Consumer) using SUMIF.
A8: ORD2006 | B8: =SUMIF(Data!A7:A207,'Count & Sum'!A8,Data!J7:J207) -> 31318.96 | D8: Tables | E8: =SUMIF(Data!H3:H202,'Count & Sum'!D8,Data!N3:N202) -> 171793.29 | G8: July | H8: =SUMIF(Data!D3:D202,'Count & Sum'!G8,Data!J3:J202) -> 427519.44 | J8: Calculated month-wise total sales using SUMIF.
A9: ORD2007 | B9: =SUMIF(Data!A8:A208,'Count & Sum'!A9,Data!J8:J208) -> 10853.73 | D9: Chairs | E9: =SUMIF(Data!H4:H203,'Count & Sum'!D9,Data!N4:N203) -> 231233.81 | G9: January | H9: =SUMIF(Data!D4:D203,'Count & Sum'!G9,Data!J4:J203) -> 265043.35 | J9: Calculated total unit price by country using SUMIF.
A10: ORD2008 | B10: =SUMIF(Data!A9:A209,'Count & Sum'!A10,Data!J9:J209) -> 6540.32 | D10: Binders | E10: =SUMIF(Data!H5:H204,'Count & Sum'!D10,Data!N5:N204) -> 201002.46 | G10: March | H10: =SUMIF(Data!D5:D204,'Count & Sum'!G10,Data!J5:J204) -> 375073.36 | J10: Calculated total sales, total quantity, and total profit using SUM.
A11: ORD2009 | B11: =SUMIF(Data!A10:A210,'Count & Sum'!A11,Data!J10:J210) -> 10918.37 | D11: Phones | E11: =SUMIF(Data!H6:H205,'Count & Sum'!D11,Data!N6:N205) -> 185142.09 | J11: Calculated product-, region-, country-, month-, and segment-wise metrics such as laptop cost, regional profit, discounts, furniture profit, quantities, and unit price using SUMIFS.
A12: ORD2010 | B12: =SUMIF(Data!A11:A211,'Count & Sum'!A12,Data!J11:J211) -> 27163.21 | D12: Laptops | E12: =SUMIF(Data!H7:H206,'Count & Sum'!D12,Data!N7:N206) -> 170717.55 | G12: Country | H12: Total Unit Price
A13: ORD2011 | B13: =SUMIF(Data!A12:A212,'Count & Sum'!A13,Data!J12:J212) -> 4746.18 | G13: India | H13: =SUMIF(Data!F2:F201,'Count & Sum'!G13,Data!O1:O201) -> 296438.12
A14: ORD2012 | B14: =SUMIF(Data!A13:A213,'Count & Sum'!A14,Data!J13:J213) -> 18491.32 | D14: CountA from A2 to A201 | E14: =COUNTA(Data!A2:A201) -> 200 | G14: UK | H14: =SUMIF(Data!F3:F202,'Count & Sum'!G14,Data!O2:O202) -> 212764.39
A15: ORD2013 | B15: =SUMIF(Data!A14:A214,'Count & Sum'!A15,Data!J14:J214) -> 10033.93 | D15: Count from B2 to B201 | E15: =COUNT(Data!B2:B201) -> 200 | G15: Germany | H15: =SUMIF(Data!F4:F203,'Count & Sum'!G15,Data!O3:O203) -> 219077.35
A16: ORD2014 | B16: =SUMIF(Data!A15:A215,'Count & Sum'!A16,Data!J15:J215) -> 22190.58 | D16: Count Blank from D2 to D201 | E16: =COUNTBLANK(Data!D2:D201) -> 0 | G16: Australia | H16: =SUMIF(Data!F5:F204,'Count & Sum'!G16,Data!O4:O204) -> 198520.9
A17: ORD2015 | B17: =SUMIF(Data!A16:A216,'Count & Sum'!A17,Data!J16:J216) -> 6220.59 | D17: CountIF from E2 to E201 | E17: =COUNTIF(Data!E2:E201,"=North") -> 44 | G17: USA | H17: =SUMIF(Data!F6:F205,'Count & Sum'!G17,Data!O5:O205) -> 208437.15
A18: ORD2016 | B18: =SUMIF(Data!A17:A217,'Count & Sum'!A18,Data!J17:J217) -> 31139.48 | D18: CountIFS | E18: =COUNTIFS(Data!F2:F201,"=India",Data!H2:H201,"=Laptops") -> 6
A19: ORD2017 | B19: =SUMIF(Data!A18:A218,'Count & Sum'!A19,Data!J18:J218) -> 37017.37 | G19: Total Sales | H19: Total Quantity | I19: Total Profit
A20: ORD2018 | B20: =SUMIF(Data!A19:A219,'Count & Sum'!A20,Data!J19:J219) -> 13318.88 | D20: Cost | E20: Profit | G20: =SUM(Data!J2:J201) -> 3969895.7 | H20: =SUM(Data!K2:K201) -> 1182 | I20: =SUM(Data!N2:N201) -> 1181509.3
A21: ORD2019 | B21: =SUMIF(Data!A20:A220,'Count & Sum'!A21,Data!J20:J220) -> 14695.56 | D21: =SUMIFS(Data!M2:M201,Data!E2:E201,"=South",Data!F2:F201,"=UK") -> 87454.17 | E21: =SUMIFS(Data!N2:N201,Data!G2:G201,"=Furniture",Data!H2:H201,"=Chairs",Data!I2:I201,"=Home Office") -> 17665.07
A22: ORD2020 | B22: =SUMIF(Data!A21:A221,'Count & Sum'!A22,Data!J21:J221) -> 24244.94
A23: ORD2021 | B23: =SUMIF(Data!A22:A222,'Count & Sum'!A23,Data!J22:J222) -> 29761.68 | D23: Cost | E23: Profit | F23: Discount | G23: Profit | H23: Quantity | I23: Unit Price
